~/workspace$ cd server && python manage.py migrate --fake-initial
Using SMTP email backend for actual email sending
Operations to perform:
  Apply all migrations: admin, api, auth, contenttypes, sessions
Running migrations:
  Applying contenttypes.0002_remove_content_type_name...Traceback (most recent call last):
  File "/home/runner/workspace/.pythonlibs/lib/python3.12/site-packages/django/db/backends/utils.py", line 103, in _execute
    return self.cursor.execute(sql)
           ^^^^^^^^^^^^^^^^^^^^^^^^
psycopg2.errors.UndefinedColumn: column "name" of relation "django_content_type" does not exist


The above exception was the direct cause of the following exception:

Traceback (most recent call last):
  File "/home/runner/workspace/server/manage.py", line 16, in <module>
    execute_from_command_line(sys.argv)
  File "/home/runner/workspace/.pythonlibs/lib/python3.12/site-packages/django/core/management/__init__.py", line 442, in execute_from_command_line
    utility.execute()
  File "/home/runner/workspace/.pythonlibs/lib/python3.12/site-packages/django/core/management/__init__.py", line 436, in execute
    self.fetch_command(subcommand).run_from_argv(self.argv)
  File "/home/runner/workspace/.pythonlibs/lib/python3.12/site-packages/django/core/management/base.py", line 416, in run_from_argv
    self.execute(*args, **cmd_options)
  File "/home/runner/workspace/.pythonlibs/lib/python3.12/site-packages/django/core/management/base.py", line 460, in execute
    output = self.handle(*args, **options)
             ^^^^^^^^^^^^^^^^^^^^^^^^^^^^^
  File "/home/runner/workspace/.pythonlibs/lib/python3.12/site-packages/django/core/management/base.py", line 107, in wrapper
    res = handle_func(*args, **kwargs)
          ^^^^^^^^^^^^^^^^^^^^^^^^^^^^
  File "/home/runner/workspace/.pythonlibs/lib/python3.12/site-packages/django/core/management/commands/migrate.py", line 353, in handle
    post_migrate_state = executor.migrate(
                         ^^^^^^^^^^^^^^^^^
  File "/home/runner/workspace/.pythonlibs/lib/python3.12/site-packages/django/db/migrations/executor.py", line 135, in migrate
    state = self._migrate_all_forwards(
            ^^^^^^^^^^^^^^^^^^^^^^^^^^^
  File "/home/runner/workspace/.pythonlibs/lib/python3.12/site-packages/django/db/migrations/executor.py", line 167, in _migrate_all_forwards
    state = self.apply_migration(
            ^^^^^^^^^^^^^^^^^^^^^
  File "/home/runner/workspace/.pythonlibs/lib/python3.12/site-packages/django/db/migrations/executor.py", line 255, in apply_migration
    state = migration.apply(state, schema_editor)
            ^^^^^^^^^^^^^^^^^^^^^^^^^^^^^^^^^^^^^
  File "/home/runner/workspace/.pythonlibs/lib/python3.12/site-packages/django/db/migrations/migration.py", line 132, in apply
    operation.database_forwards(
  File "/home/runner/workspace/.pythonlibs/lib/python3.12/site-packages/django/db/migrations/operations/fields.py", line 241, in database_forwards
    schema_editor.alter_field(from_model, from_field, to_field)
  File "/home/runner/workspace/.pythonlibs/lib/python3.12/site-packages/django/db/backends/base/schema.py", line 912, in alter_field
    self._alter_field(
  File "/home/runner/workspace/.pythonlibs/lib/python3.12/site-packages/django/db/backends/postgresql/schema.py", line 274, in _alter_field
    super()._alter_field(
  File "/home/runner/workspace/.pythonlibs/lib/python3.12/site-packages/django/db/backends/base/schema.py", line 1165, in _alter_field
    self.execute(
  File "/home/runner/workspace/.pythonlibs/lib/python3.12/site-packages/django/db/backends/postgresql/schema.py", line 48, in execute
    return super().execute(sql, None)
           ^^^^^^^^^^^^^^^^^^^^^^^^^^
  File "/home/runner/workspace/.pythonlibs/lib/python3.12/site-packages/django/db/backends/base/schema.py", line 204, in execute
    cursor.execute(sql, params)
  File "/home/runner/workspace/.pythonlibs/lib/python3.12/site-packages/django/db/backends/utils.py", line 122, in execute
    return super().execute(sql, params)
           ^^^^^^^^^^^^^^^^^^^^^^^^^^^^
  File "/home/runner/workspace/.pythonlibs/lib/python3.12/site-packages/django/db/backends/utils.py", line 79, in execute
    return self._execute_with_wrappers(
           ^^^^^^^^^^^^^^^^^^^^^^^^^^^^
  File "/home/runner/workspace/.pythonlibs/lib/python3.12/site-packages/django/db/backends/utils.py", line 92, in _execute_with_wrappers
    return executor(sql, params, many, context)
           ^^^^^^^^^^^^^^^^^^^^^^^^^^^^^^^^^^^^
  File "/home/runner/workspace/.pythonlibs/lib/python3.12/site-packages/django/db/backends/utils.py", line 100, in _execute
    with self.db.wrap_database_errors:
         ^^^^^^^^^^^^^^^^^^^^^^^^^^^^
  File "/home/runner/workspace/.pythonlibs/lib/python3.12/site-packages/django/db/utils.py", line 91, in __exit__
    raise dj_exc_value.with_traceback(traceback) from exc_value
  File "/home/runner/workspace/.pythonlibs/lib/python3.12/site-packages/django/db/backends/utils.py", line 103, in _execute
    return self.cursor.execute(sql)
           ^^^^^^^^^^^^^^^^^^^^^^^^
django.db.utils.ProgrammingError: column "name" of relation "django_content_type" does not exist